Workbook

Sheet Страны
B1: Страна, куда доставляются почтовые отправления
B2: Страна, куда закрыт прием почтовых отправлений
A4: Регион | B4: № | C4: Страна | D4: Ориентировочный срок доставки (календарных дней) | E4: Способ доставки | F4: Мелкий Пакет | G4: Посылка мжд наземная | H4: Посылка мжд авиа | I4: EMS мжд | J4: Мешки М | K4: Письма, Почтовые карточки | L4: Бандероли | M4: Комментарий
A5: Ближнее зарубежье | B5: 1 | C5: АБХАЗИЯ | D5: 12-20 дней | E5: Доставка наземным транспортом | F5: Да | G5: Да | H5: Нет | I5: Нет | J5: Да | K5: =VLOOKUP($C5,[1]Страны!$C$4:$M$215,9,0) -> Да | L5: =VLOOKUP($C5,[1]Страны!$C$4:$M$215,10,0) -> Да
A6: Океания | B6: 2 | C6: АВСТРАЛИЯ | D6: сроки будут определены по мере разработки и запуска логистических решений | E6: Логистическое решение по доставке в страну временно отсутствует | F6: Нет | G6: Нет | H6: Нет | I6: Нет | J6: Нет | K6: =VLOOKUP($C6,[1]Страны!$C$4:$M$215,9,0) -> Нет | L6: =VLOOKUP($C6,[1]Страны!$C$4:$M$215,10,0) -> Нет
A7: Европа | B7: 3 | C7: АВСТРИЯ | D7: 15-30 дней | E7: Доставка возможна наземным и авиа транспортом | F7: Да | G7: Да | H7: Да | I7: Да | J7: Нет | K7: =VLOOKUP($C7,[1]Страны!$C$4:$M$215,9,0) -> Да | L7: =VLOOKUP($C7,[1]Страны!$C$4:$M$215,10,0) -> Да
A8: Ближнее зарубежье | B8: 4 | C8: АЗЕРБАЙДЖАН | D8: 14-17 дней | E8: Доставка авиатранспортом | F8: Да | G8: Нет | H8: Да | I8: Да | J8: Да | K8: =VLOOKUP($C8,[1]Страны!$C$4:$M$215,9,0) -> Да | L8: =VLOOKUP($C8,[1]Страны!$C$4:$M$215,10,0) -> Да
A9: Европа | B9: 5 | C9: АЛБАНИЯ | D9: 15-25 дней | E9: Доставка авиатранспортом | F9: Да | G9: Нет | H9: Да | I9: Да | J9: Да | K9: =VLOOKUP($C9,[1]Страны!$C$4:$M$215,9,0) -> Да | L9: =VLOOKUP($C9,[1]Страны!$C$4:$M$215,10,0) -> Да
A10: Африка | B10: 6 | C10: АЛЖИР | D10: 18-32 дней | E10: Доставка авиатранспортом | F10: Да | G10: Нет | H10: Да | I10: Да | J10: Да | K10: =VLOOKUP($C10,[1]Страны!$C$4:$M$215,9,0) -> Да | L10: =VLOOKUP($C10,[1]Страны!$C$4:$M$215,10,0) -> Да
A11: Африка | B11: 7 | C11: АНГОЛА | D11: 30-45 дней | E11: Доставка авиатранспортом | F11: Нет | G11: Нет | H11: Нет | I11: Да | J11: Нет | K11: =VLOOKUP($C11,[1]Страны!$C$4:$M$215,9,0) -> Да | L11: =VLOOKUP($C11,[1]Страны!$C$4:$M$215,10,0) -> Да
A12: Европа | B12: 8 | C12: АНДОРРА | D12: 25-35 дней | E12: Доставка возможна наземным и авиа транспортом | F12: Да | G12: Да | H12: Да | I12: Да | J12: Да | K12: =VLOOKUP($C12,[1]Страны!$C$4:$M$215,9,0) -> Да | L12: =VLOOKUP($C12,[1]Страны!$C$4:$M$215,10,0) -> Да
A13: Латинская и Южная Америка | B13: 9 | C13: АНТИГУА И БАРБУДА | D13: сроки будут определены по мере разработки и запуска логистических решений | E13: Логистическое решение по доставке в страну временно отсутствует | F13: Нет | G13: Нет | H13: Нет | I13: Нет | J13: Нет | K13: =VLOOKUP($C13,[1]Страны!$C$4:$M$215,9,0) -> Нет | L13: =VLOOKUP($C13,[1]Страны!$C$4:$M$215,10,0) -> Нет
A14: Латинская и Южная Америка | B14: 10 | C14: АРГЕНТИНА | D14: 30-45 дней | E14: Доставка авиатранспортом | F14: Да | G14: Нет | H14: Да | I14: Да | J14: Да | K14: =VLOOKUP($C14,[1]Страны!$C$4:$M$215,9,0) -> Да | L14: =VLOOKUP($C14,[1]Страны!$C$4:$M$215,10,0) -> Да
A15: Ближнее зарубежье | B15: 11 | C15: АРМЕНИЯ | D15: 10-15 дней | E15: Доставка авиатранспортом | F15: Да | G15: Да | H15: Да | I15: Да | J15: Да | K15: =VLOOKUP($C15,[1]Страны!$C$4:$M$215,9,0) -> Да | L15: =VLOOKUP($C15,[1]Страны!$C$4:$M$215,10,0) -> Да
A16: Азия | B16: 12 | C16: АФГАНИСТАН | D16: 15-30 дней | E16: Доставка авиатранспортом | F16: Да | G16: Нет | H16: Да | I16: Да | J16: Да | K16: =VLOOKUP($C16,[1]Страны!$C$4:$M$215,9,0) -> Да | L16: =VLOOKUP($C16,[1]Страны!$C$4:$M$215,10,0) -> Да
... A97: Африка | B97: 93 | C97: КОТ Д'ИВУАР | D97: 20-30 дней | E97: Доставка авиатранспортом | F97: Нет | G97: Нет | H97: Нет | I97: Да | J97: Нет | K97: =VLOOKUP($C97,[1]Страны!$C$4:$M$215,9,0) -> Да | L97: =VLOOKUP($C97,[1]Страны!$C$4:$M$215,10,0) -> Да
A98: Латинская и Южная Америка | B98: 94 | C98: КУБА | D98: 25-40 дней | E98: Доставка авиатранспортом * | F98: Да | G98: Нет | H98: Да | I98: Да | J98: Да | K98: =VLOOKUP($C98,[1]Страны!$C$4:$M$215,9,0) -> Да | L98: =VLOOKUP($C98,[1]Страны!$C$4:$M$215,10,0) -> Да | M98: * Доставка до Европы авто
A99: Ближний Восток | B99: 95 | C99: КУВЕЙТ | D99: 20-30 дней | E99: Доставка авиатранспортом | F99: Да | G99: Нет | H99: Да | I99: Да | J99: Да | K99: =VLOOKUP($C99,[1]Страны!$C$4:$M$215,9,0) -> Да | L99: =VLOOKUP($C99,[1]Страны!$C$4:$M$215,10,0) -> Да
A100: Латинская и Южная Америка | B100: 96 | C100: КЮРАСАО | D100: сроки будут определены по мере разработки и запуска логистических решений | E100: Логистическое решение по доставке в страну временно отсутствует | F100: Нет | G100: Нет | H100: Нет | I100: Нет | J100: Нет | K100: =VLOOKUP($C100,[1]Страны!$C$4:$M$215,9,0) -> Нет | L100: =VLOOKUP($C100,[1]Страны!$C$4:$M$215,10,0) -> Нет
A101: Азия | B101: 97 | C101: ЛАОС | D101: 20-30 дней | E101: Доставка авиатранспортом | F101: Нет | G101: Нет | H101: Нет | I101: Да | J101: Нет | K101: =VLOOKUP($C101,[1]Страны!$C$4:$M$215,9,0) -> Да | L101: =VLOOKUP($C101,[1]Страны!$C$4:$M$215,10,0) -> Да
A102: Европа | B102: 98 | C102: ЛАТВИЯ | D102: 15-25 дней | E102: Доставка возможна наземным и авиа транспортом | F102: Да | G102: Да | H102: Да | I102: Да | J102: Да | K102: =VLOOKUP($C102,[1]Страны!$C$4:$M$215,9,0) -> Да | L102: =VLOOKUP($C102,[1]Страны!$C$4:$M$215,10,0) -> Да
A103: Африка | B103: 99 | C103: ЛЕСОТО | D103: сроки будут определены по мере разработки и запуска логистических решений | E103: Логистическое решение по доставке в страну временно отсутствует | F103: Нет | G103: Нет | H103: Нет | I103: Нет | J103: Нет | K103: =VLOOKUP($C103,[1]Страны!$C$4:$M$215,9,0) -> Нет | L103: =VLOOKUP($C103,[1]Страны!$C$4:$M$215,10,0) -> Нет
A104: Африка | B104: 100 | C104: ЛИБЕРИЯ | D104: 20-30 дней | E104: Доставка авиатранспортом | F104: Да | G104: Нет | H104: Нет | I104: Да | J104: Да | K104: =VLOOKUP($C104,[1]Страны!$C$4:$M$215,9,0) -> Да | L104: =VLOOKUP($C104,[1]Страны!$C$4:$M$215,10,0) -> Да
A105: Ближний Восток | B105: 101 | C105: ЛИВАН | D105: 20-30 дней | E105: Доставка авиатранспортом | F105: Да | G105: Нет | H105: Да | I105: Да | J105: Да | K105: =VLOOKUP($C105,[1]Страны!$C$4:$M$215,9,0) -> Да | L105: =VLOOKUP($C105,[1]Страны!$C$4:$M$215,10,0) -> Да
A106: Африка | B106: 102 | C106: ЛИВИЯ | D106: сроки будут определены по мере разработки и запуска логистических решений | E106: Логистическое решение по доставке в страну временно отсутствует | F106: Нет | G106: Нет | H106: Нет | I106: Нет | J106: Нет | K106: =VLOOKUP($C106,[1]Страны!$C$4:$M$215,9,0) -> Нет | L106: =VLOOKUP($C106,[1]Страны!$C$4:$M$215,10,0) -> Нет
A107: Европа | B107: 103 | C107: ЛИТВА | D107: 15-25 дней | E107: Доставка возможна наземным и авиа транспортом | F107: Да | G107: Да | H107: Да | I107: Да | J107: Да | K107: =VLOOKUP($C107,[1]Страны!$C$4:$M$215,9,0) -> Да | L107: =VLOOKUP($C107,[1]Страны!$C$4:$M$215,10,0) -> Да
A108: Европа | B108: 104 | C108: ЛИХТЕНШТЕЙН | D108: 15-25 дней | E108: Доставка возможна наземным и авиа транспортом | F108: Да | G108: Да | H108: Да | I108: Да | J108: Нет | K108: =VLOOKUP($C108,[1]Страны!$C$4:$M$215,9,0) -> Да | L108: =VLOOKUP($C108,[1]Страны!$C$4:$M$215,10,0) -> Да
A109: Европа | B109: 105 | C109: ЛЮКСЕМБУРГ | D109: 25-35 дней | E109: Доставка возможна наземным и авиа транспортом | F109: Да | G109: Да | H109: Да | I109: Да | J109: Да | K109: =VLOOKUP($C109,[1]Страны!$C$4:$M$215,9,0) -> Да | L109: =VLOOKUP($C109,[1]Страны!$C$4:$M$215,10,0) -> Да
A110: Африка | B110: 106 | C110: МАВРИКИЙ | D110: 15-30 дней | E110: Доставка авиатранспортом | F110: Да | G110: Нет | H110: Да | I110: Да | J110: Нет | K110: =VLOOKUP($C110,[1]Страны!$C$4:$M$215,9,0) -> Да | L110: =VLOOKUP($C110,[1]Страны!$C$4:$M$215,10,0) -> Да
... A163: Латинская и Южная Америка | B163: 159 | C163: СЕНТ-ЛЮСИЯ | D163: сроки будут определены по мере разработки и запуска логистических решений | E163: Логистическое решение по доставке в страну временно отсутствует | F163: Нет | G163: Нет | H163: Нет | I163: Нет | J163: Нет | K163: =VLOOKUP($C163,[1]Страны!$C$4:$M$215,9,0) -> Нет | L163: =VLOOKUP($C163,[1]Страны!$C$4:$M$215,10,0) -> Нет
A164: Латинская и Южная Америка | B164: 160 | C164: СЕН-БАРТЕЛЕМИ | D164: сроки будут определены по мере разработки и запуска логистических решений | E164: Логистическое решение по доставке в страну временно отсутствует | F164: Нет | G164: Нет | H164: Нет | I164: Нет | J164: Нет | K164: Нет | L164: Нет
A165: Европа | B165: 161 | C165: СЕРБИЯ | D165: 10-15 дней | E165: Доставка авиатранспортом | F165: Да | G165: Нет | H165: Да | I165: Да | J165: Да | K165: =VLOOKUP($C165,[1]Страны!$C$4:$M$215,9,0) -> Да | L165: =VLOOKUP($C165,[1]Страны!$C$4:$M$215,10,0) -> Да
A166: Азия | B166: 162 | C166: СИНГАПУР | D166: 10-20 дней | E166: Доставка авиатранспортом | F166: Да | G166: Нет | H166: Да | I166: Да | J166: Да | K166: =VLOOKUP($C166,[1]Страны!$C$4:$M$215,9,0) -> Да | L166: =VLOOKUP($C166,[1]Страны!$C$4:$M$215,10,0) -> Да
A167: Ближний Восток | B167: 163 | C167: СИРИЙСКАЯ АРАБСКАЯ РЕСПУБЛИКА | D167: сроки будут определены по мере разработки и запуска логистических решений | E167: Логистическое решение по доставке в страну временно отсутствует | F167: Нет | G167: Нет | H167: Нет | I167: Нет | J167: Нет | K167: =VLOOKUP($C167,[1]Страны!$C$4:$M$215,9,0) -> Нет | L167: =VLOOKUP($C167,[1]Страны!$C$4:$M$215,10,0) -> Нет
A168: Европа | B168: 164 | C168: СЛОВАКИЯ | D168: 15-30 дней | E168: Доставка возможна наземным и авиа транспортом | F168: Да | G168: Да | H168: Да | I168: Да | J168: Да | K168: =VLOOKUP($C168,[1]Страны!$C$4:$M$215,9,0) -> Да | L168: =VLOOKUP($C168,[1]Страны!$C$4:$M$215,10,0) -> Да
A169: Европа | B169: 165 | C169: СЛОВЕНИЯ | D169: 15-30 дней | E169: Доставка возможна наземным и авиа транспортом | F169: Да | G169: Да | H169: Да | I169: Да | J169: Нет | K169: =VLOOKUP($C169,[1]Страны!$C$4:$M$215,9,0) -> Да | L169: =VLOOKUP($C169,[1]Страны!$C$4:$M$215,10,0) -> Да
A170: Северная Америка | B170: 166 | C170: СОЕДИНЕННЫЕ ШТАТЫ АМЕРИКИ | D170: 10-25 дней | E170: Доставка авиатранспортом* | F170: Да* | G170: Нет | H170: Да* | I170: Да* | J170: Нет | K170: =VLOOKUP($C170,[1]Страны!$C$4:$M$215,9,0) -> Да | L170: Нет | M170: * Письменная корреспонденция, а также подарки, коммерческие образцы и документы доставляются. Товары на продажу не доставляются.
A171: Океания | B171: 167 | C171: СОЛОМОНОВЫ ОСТРОВА | D171: сроки будут определены по мере разработки и запуска логистических решений | E171: Логистическое решение по доставке в страну временно отсутствует | F171: Нет | G171: Нет | H171: Нет | I171: Нет | J171: Нет | K171: =VLOOKUP($C171,[1]Страны!$C$4:$M$215,9,0) -> Нет | L171: =VLOOKUP($C171,[1]Страны!$C$4:$M$215,10,0) -> Нет
A172: Африка | B172: 168 | C172: СОМАЛИ | D172: сроки будут определены по мере разработки и запуска логистических решений | E172: Логистическое решение по доставке в страну временно отсутствует | F172: Нет | G172: Нет | H172: Нет | I172: Нет | J172: Нет | K172: =VLOOKUP($C172,[1]Страны!$C$4:$M$215,9,0) -> Нет | L172: =VLOOKUP($C172,[1]Страны!$C$4:$M$215,10,0) -> Нет
A173: Африка | B173: 169 | C173: СУДАН | D173: сроки будут определены по мере разработки и запуска логистических решений | E173: Логистическое решение по доставке в страну временно отсутствует | F173: Нет | G173: Нет | H173: Нет | I173: Нет | J173: Нет | K173: =VLOOKUP($C173,[1]Страны!$C$4:$M$215,9,0) -> Нет | L173: =VLOOKUP($C173,[1]Страны!$C$4:$M$215,10,0) -> Нет
...
